{
 "cells": [
  {
   "cell_type": "markdown",
   "metadata": {},
   "source": [
    "# Handle exceptions\n",
    "\n",
    "When you first find exceptions that show large tracebacks as output, you might be tempted to catch every error to prevent that from happening.\n",
    "\n",
    "If you're in a mission to Mars, what could you do if a text on the navigation system reads \"an error occurred\"? Imagine that there's no other information or context, just a blinking red light with the error text. As a developer, it's useful to put yourself on the other side of the program: what can a user do when there's an error?\n",
    "\n",
    "Although this module covers how to handle exceptions by catching them, it's not necessary to catch exceptions all the time. Sometimes it's useful to let exceptions be raised so other callers can deal with the errors.\n",
    "\n",
    "### Try and except blocks\n",
    "Let's use the navigator example to create code that opens configuration files for the Mars mission. Configuration files can have all kinds of problems, so it's critical to report problems accurately when they come up. We know that if a file or directory doesn't exist, FileNotFoundError is raised. If we want to handle that exception, we can do that with a try and except block:"
   ]
  },
  {
   "cell_type": "code",
   "execution_count": 14,
   "metadata": {},
   "outputs": [
    {
     "name": "stdout",
     "output_type": "stream",
     "text": [
      "Couldn't find the config.txt file!\n"
     ]
    }
   ],
   "source": [
    "try:\n",
    "     open('config.txt')\n",
    "except FileNotFoundError:\n",
    "     print(\"Couldn't find the config.txt file!\")"
   ]
  },
  {
   "cell_type": "markdown",
   "metadata": {},
   "source": [
    "After the try keyword, you add code that has the potential to cause an exception. Next, you add the except keyword along with the possible exception, followed by any code that needs to run when that condition happens. Because config.txt doesn't exist in the system, Python prints that the configuration file is not there. The try and except block, along with a helpful message, prevents a traceback and still informs the user about the problem.\n",
    "\n",
    "Although a file that doesn't exist is common, it isn't the only error you might find. Invalid file permissions can prevent reading a file, even if the file exists. Let's create a new Python file called config.py in Visual Studio Code. Add the following code to the file that finds and reads the navigation system's configuration file:\n",
    "\n",
    "Python"
   ]
  },
  {
   "cell_type": "code",
   "execution_count": 15,
   "metadata": {},
   "outputs": [
    {
     "name": "stdout",
     "output_type": "stream",
     "text": [
      "Couldn't find the config.txt file!\n"
     ]
    }
   ],
   "source": [
    "def main():\n",
    "    try:\n",
    "        configuration = open('config.txt')\n",
    "    except FileNotFoundError:\n",
    "        print(\"Couldn't find the config.txt file!\")\n",
    "\n",
    "\n",
    "if __name__ == '__main__':\n",
    "    main()"
   ]
  },
  {
   "cell_type": "markdown",
   "metadata": {},
   "source": [
    "A useless way of handling this error would be to catch all possible exceptions to prevent a traceback. To understand why catching all exceptions is problematic, try it by updating the main() function in the newly created config.py file:"
   ]
  },
  {
   "cell_type": "code",
   "execution_count": 16,
   "metadata": {},
   "outputs": [
    {
     "name": "stdout",
     "output_type": "stream",
     "text": [
      "Couldn't find the config.txt file!\n"
     ]
    }
   ],
   "source": [
    "def main():\n",
    "    try:\n",
    "        configuration = open('config.txt')\n",
    "    except Exception:\n",
    "        print(\"Couldn't find the config.txt file!\")\n",
    "\n",
    "if __name__ == '__main__':\n",
    "    main()"
   ]
  },
  {
   "cell_type": "markdown",
   "metadata": {},
   "source": [
    "The problem now is that the error message is incorrect. The directory does exist, but it has different permissions and Python can't read it. When you're dealing with software errors, it can be frustrating to have errors that:\n",
    "\n",
    "* Don't indicate what the real problem is.\n",
    "* Give output that doesn't match the actual problem.\n",
    "* Don't hint at what can be done to fix the problem.\n",
    "\n",
    "Let's fix this piece of code to address all these frustrations. Revert to catching FileNotFoundError, and then add another except block to catch PermissionError:"
   ]
  },
  {
   "cell_type": "code",
   "execution_count": 17,
   "metadata": {},
   "outputs": [
    {
     "name": "stdout",
     "output_type": "stream",
     "text": [
      "Couldn't find the config.txt file!\n"
     ]
    }
   ],
   "source": [
    "def main():\n",
    "    try:\n",
    "        configuration = open('config.txt')\n",
    "    except FileNotFoundError:\n",
    "        print(\"Couldn't find the config.txt file!\")\n",
    "    except IsADirectoryError:\n",
    "        print(\"Found config.txt but it is a directory, couldn't read it\")\n",
    "\n",
    "if __name__ == '__main__':\n",
    "    main()"
   ]
  },
  {
   "cell_type": "markdown",
   "metadata": {},
   "source": [
    "Now delete the config.txt directory to ensure that the first except block will be reached instead:"
   ]
  },
  {
   "cell_type": "code",
   "execution_count": 18,
   "metadata": {},
   "outputs": [
    {
     "name": "stdout",
     "output_type": "stream",
     "text": [
      "Couldn't find the config.txt file!\n"
     ]
    }
   ],
   "source": [
    "def main():\n",
    "    try:\n",
    "        configuration = open('config.txt')\n",
    "    except FileNotFoundError:\n",
    "        print(\"Couldn't find the config.txt file!\")\n",
    "    except IsADirectoryError:\n",
    "        print(\"Found config.txt but it is a directory, couldn't read it\")\n",
    "\n",
    "if __name__ == '__main__':\n",
    "    main()"
   ]
  },
  {
   "cell_type": "markdown",
   "metadata": {},
   "source": [
    "When errors are of a similar nature and there's no need to handle them individually, you can group the exceptions together as one by using parentheses in the except line. For example, if the navigation system is under heavy loads and the file system becomes too busy, it makes sense to catch BlockingIOError and TimeOutError together:"
   ]
  },
  {
   "cell_type": "code",
   "execution_count": 19,
   "metadata": {},
   "outputs": [],
   "source": [
    "def main():\n",
    "    try:\n",
    "        configuration = open('config.txt')\n",
    "    except FileNotFoundError:\n",
    "        print(\"Couldn't find the config.txt file!\")\n",
    "    except IsADirectoryError:\n",
    "        print(\"Found config.txt but it is a directory, couldn't read it\")\n",
    "    except (BlockingIOError, TimeoutError):\n",
    "        print(\"Filesystem under heavy load, can't complete reading configuration file\")"
   ]
  },
  {
   "cell_type": "markdown",
   "metadata": {},
   "source": [
    "***Tip***\n",
    "\n",
    "Even though you can group exceptions together, do so only when there's no need to handle them individually. Avoid grouping many exceptions together to provide a generalized error message."
   ]
  },
  {
   "cell_type": "markdown",
   "metadata": {},
   "source": [
    "If you need to access the error that's associated with the exception, you must update the except line to include the as keyword. This technique is handy if an exception is too generic and the error message can be useful:"
   ]
  },
  {
   "cell_type": "code",
   "execution_count": 20,
   "metadata": {},
   "outputs": [
    {
     "name": "stdout",
     "output_type": "stream",
     "text": [
      "Got a problem trying to read the file: [Errno 2] No such file or directory: 'mars.jpg'\n"
     ]
    }
   ],
   "source": [
    "try:\n",
    "    open(\"mars.jpg\")\n",
    "except FileNotFoundError as err:\n",
    "     print(\"Got a problem trying to read the file:\", err)"
   ]
  },
  {
   "cell_type": "markdown",
   "metadata": {},
   "source": [
    "In this case, as err means that err becomes a variable with the exception object as a value. It then uses this value to print the error message that's associated with the exception. Another reason to use this technique is to access attributes of the error directly. For example, if you're catching a more generic OSError exception, which is the parent exception of both FilenotFoundError and PermissionError, you can tell them apart by the .errno attribute:"
   ]
  },
  {
   "cell_type": "code",
   "execution_count": 21,
   "metadata": {},
   "outputs": [
    {
     "name": "stdout",
     "output_type": "stream",
     "text": [
      "Couldn't find the config.txt file!\n"
     ]
    }
   ],
   "source": [
    "try:\n",
    "    open(\"config.txt\")\n",
    "except OSError as err:\n",
    "     if err.errno == 2:\n",
    "         print(\"Couldn't find the config.txt file!\")\n",
    "     elif err.errno == 13:\n",
    "        print(\"Found config.txt but couldn't read it\")"
   ]
  },
  {
   "cell_type": "markdown",
   "metadata": {},
   "source": [
    "Always try to use the technique that provides the best readability for the code and helps maintain it in the future. Sometimes it's necessary to use less readable code to offer a better user experience when an error happens."
   ]
  }
 ],
 "metadata": {
  "kernelspec": {
   "display_name": "base",
   "language": "python",
   "name": "python3"
  },
  "language_info": {
   "codemirror_mode": {
    "name": "ipython",
    "version": 3
   },
   "file_extension": ".py",
   "mimetype": "text/x-python",
   "name": "python",
   "nbconvert_exporter": "python",
   "pygments_lexer": "ipython3",
   "version": "3.11.7"
  }
 },
 "nbformat": 4,
 "nbformat_minor": 2
}
